Workbook

Sheet Inventory
D2: EXPIRED VALUE | E2: TOTAL STOCK VALUE | F2: RESTOCK COUNT | G2: EXPIRED FLAG COUNT | H2: TOTAL REVENUE VALUE
D3: =SUMIF(Inventory[Expired Flag],"EXPIRED",Inventory[Unit Cost]) -> 3400 | E3: =SUMIF(Inventory[Expired Flag],"",Inventory[Unit Cost]) -> 2250 | F3: =COUNTIF(Inventory[Restock Flag],"RESTOCK") -> 1 | G3: =COUNTIF(Inventory[Expired Flag],"EXPIRED") -> 4 | H3: =SUMIF(Inventory[Expired Flag],"",Inventory[Sale Price]) -> 29500
A7: Product ID | B7: Product Name | C7: Product Category | D7: M.F Date | E7: E.X.P Date | F7: Expired Flag | G7: Opening Stock | H7: Purchased Qty | I7: Sold Qty | J7: Stock Level | K7: Unit Size | L7: Unit Cost | M7: Sale Price | N7: Inventory Value | O7: Restock Threshold | P7: Restock Flag
A8: CM001 | B8: Panadol | C8: Analgesic | D8: 44693 | E8: 46883 | F8: =IF(Inventory[[#This Row],[Product Category]]="","",IF(E8<TODAY(),"EXPIRED", IF(E8<=TODAY()+30,"<30 DAYS", IF(E8<=TODAY()+60,"<60 DAYS",IF(E8=0,"",""))))) | G8: 250 | H8: =SUMIF(Purchases[Product ID],A8,Purchases[Quantity]) -> 60 | I8: =SUMIF(Sales[Product Name],Inventory[[#This Row],[Product Name]],Sales[Quantity Sold]) -> 80 | J8: =G8+H8-I8 -> 230 | K8: Piece | L8: 700 | M8: 700 | N8: =J8*L8 -> 161000 | O8: 230 | P8: {=IF(J8<=O8,"RESTOCK",IF(Inventory[Product Name]="","","OK"))} -> RESTOCK
A9: CM002 | B9: Babyrex | C9: Analgesic | D9: 44694 | E9: 46153 | F9: =IF(Inventory[[#This Row],[Product Category]]="","",IF(E9<TODAY(),"EXPIRED", IF(E9<=TODAY()+30,"<30 DAYS", IF(E9<=TODAY()+60,"<60 DAYS",IF(E9=0,"",""))))) -> EXPIRED | G9: 50 | H9: =SUMIF(Purchases[Product ID],A9,Purchases[Quantity]) -> 20 | I9: =SUMIF(Sales[Product Name],Inventory[[#This Row],[Product Name]],Sales[Quantity Sold]) -> 50 | J9: =G9+H9-I9 -> 20 | L9: 700 | M9: 500 | N9: =J9*L9 -> 14000 | P9: =IF(J9<=O9,"RESTOCK","OK") -> OK
A10: CM003 | B10: Lumapril | C10: Antibiotic | D10: 44695 | E10: 46519 | F10: =IF(Inventory[[#This Row],[Product Category]]="","",IF(E10<TODAY(),"EXPIRED", IF(E10<=TODAY()+30,"<30 DAYS", IF(E10<=TODAY()+60,"<60 DAYS",IF(E10=0,"",""))))) | G10: 150 | H10: =SUMIF(Purchases[Product ID],A10,Purchases[Quantity]) -> 30 | I10: =SUMIF(Sales[Product Name],Inventory[[#This Row],[Product Name]],Sales[Quantity Sold]) -> 4 | J10: =G10+H10-I10 -> 176 | L10: 450 | M10: 300 | N10: =J10*L10 -> 79200 | P10: =IF(J10<=O10,"RESTOCK","OK") -> OK
A11: CM004 | B11: Fansidar | C11: Antimalaria | D11: 44696 | E11: 46520 | F11: =IF(Inventory[[#This Row],[Product Category]]="","",IF(E11<TODAY(),"EXPIRED", IF(E11<=TODAY()+30,"<30 DAYS", IF(E11<=TODAY()+60,"<60 DAYS",IF(E11=0,"",""))))) | G11: 300 | H11: =SUMIF(Purchases[Product ID],A11,Purchases[Quantity]) -> 30 | I11: =SUMIF(Sales[Product Name],Inventory[[#This Row],[Product Name]],Sales[Quantity Sold]) -> 20 | J11: =G11+H11-I11 -> 310 | L11: 600 | M11: 800 | N11: =J11*L11 -> 186000 | P11: =IF(J11<=O11,"RESTOCK","OK") -> OK
A12: CM005 | B12: Glanil | C12: Antidiabetic | D12: 44697 | E12: 45791 | F12: =IF(Inventory[[#This Row],[Product Category]]="","",IF(E12<TODAY(),"EXPIRED", IF(E12<=TODAY()+30,"<30 DAYS", IF(E12<=TODAY()+60,"<60 DAYS",IF(E12=0,"",""))))) -> EXPIRED | G12: 450 | H12: =SUMIF(Purchases[Product ID],A12,Purchases[Quantity]) -> 10 | I12: =SUMIF(Sales[Product Name],Inventory[[#This Row],[Product Name]],Sales[Quantity Sold]) -> 66 | J12: =G12+H12-I12 -> 394 | L12: 950 | M12: 1000 | N12: =J12*L12 -> 374300 | P12: =IF(J12<=O12,"RESTOCK","OK") -> OK
A13: CM006 | B13: Glucophage | C13: Antidiabetic | D13: 44698 | E13: 46888 | F13: =IF(Inventory[[#This Row],[Product Category]]="","",IF(E13<TODAY(),"EXPIRED", IF(E13<=TODAY()+30,"<30 DAYS", IF(E13<=TODAY()+60,"<60 DAYS",IF(E13=0,"",""))))) | G13: 250 | H13: =SUMIF(Purchases[Product ID],A13,Purchases[Quantity]) -> 0 | I13: =SUMIF(Sales[Product Name],Inventory[[#This Row],[Product Name]],Sales[Quantity Sold]) -> 0 | J13: =G13+H13-I13 -> 250 | N13: =J13*L13 -> 0 | P13: =IF(J13<=O13,"RESTOCK","OK") -> OK
A14: CM007 | B14: Goko Cleanser 100ml | C14: Antibiotic | D14: 44699 | E14: 45793 | F14: =IF(Inventory[[#This Row],[Product Category]]="","",IF(E14<TODAY(),"EXPIRED", IF(E14<=TODAY()+30,"<30 DAYS", IF(E14<=TODAY()+60,"<60 DAYS",IF(E14=0,"",""))))) -> EXPIRED | G14: 120 | H14: =SUMIF(Purchases[Product ID],A14,Purchases[Quantity]) -> 0 | I14: =SUMIF(Sales[Product Name],Inventory[[#This Row],[Product Name]],Sales[Quantity Sold]) -> 0 | J14: =G14+H14-I14 -> 120 | L14: 800 | N14: =J14*L14 -> 96000 | P14: =IF(J14<=O14,"RESTOCK","OK") -> OK
A15: CM008 | B15: Strepsil | C15: Suppliment | D15: 44700 | E15: 46524 | F15: =IF(Inventory[[#This Row],[Product Category]]="","",IF(E15<TODAY(),"EXPIRED", IF(E15<=TODAY()+30,"<30 DAYS", IF(E15<=TODAY()+60,"<60 DAYS",IF(E15=0,"",""))))) | G15: 98 | H15: =SUMIF(Purchases[Product ID],A15,Purchases[Quantity]) -> 0 | I15: =SUMIF(Sales[Product Name],Inventory[[#This Row],[Product Name]],Sales[Quantity Sold]) -> 25 | J15: =G15+H15-I15 -> 73 | L15: 500 | M15: 700 | N15: =J15*L15 -> 36500 | P15: =IF(J15<=O15,"RESTOCK","OK") -> OK
A16: CM009 | B16: Bunto | C16: Suppliment | D16: 44701 | E16: 47256 | F16: =IF(Inventory[[#This Row],[Product Category]]="","",IF(E16<TODAY(),"EXPIRED", IF(E16<=TODAY()+30,"<30 DAYS", IF(E16<=TODAY()+60,"<60 DAYS",IF(E16=0,"",""))))) | G16: 156 | H16: =SUMIF(Purchases[Product ID],A16,Purchases[Quantity]) -> 0 | I16: =SUMIF(Sales[Product Name],Inventory[[#This Row],[Product Name]],Sales[Quantity Sold]) -> 0 | J16: =G16+H16-I16 -> 156 | N16: =J16*L16 -> 0 | P16: =IF(J16<=O16,"RESTOCK","OK") -> OK
A17: CM010 | B17: Paracetamol | C17: Analgesic | D17: 44702 | E17: 46345 | F17: =IF(Inventory[[#This Row],[Product Category]]="","",IF(E17<TODAY(),"EXPIRED", IF(E17<=TODAY()+30,"<30 DAYS", IF(E17<=TODAY()+60,"<60 DAYS",IF(E17=0,"",""))))) | G17: 3330 | H17: =SUMIF(Purchases[Product ID],A17,Purchases[Quantity]) -> 0 | I17: =SUMIF(Sales[Product Name],Inventory[[#This Row],[Product Name]],Sales[Quantity Sold]) -> 0 | J17: =G17+H17-I17 -> 3330 | N17: =J17*L17 -> 0 | P17: =IF(J17<=O17,"RESTOCK","OK") -> OK
A18: CM011 | B18: Perfectil | C18: Suppliment | D18: 44703 | E18: 46223 | F18: =IF(Inventory[[#This Row],[Product Category]]="","",IF(E18<TODAY(),"EXPIRED", IF(E18<=TODAY()+30,"<30 DAYS", IF(E18<=TODAY()+60,"<60 DAYS",IF(E18=0,"",""))))) -> <30 DAYS | G18: 410 | H18: =SUMIF(Purchases[Product ID],A18,Purchases[Quantity]) -> 30 | I18: =SUMIF(Sales[Product Name],Inventory[[#This Row],[Product Name]],Sales[Quantity Sold]) -> 0 | J18: =G18+H18-I18 -> 440 | N18: =J18*L18 -> 0 | P18: =IF(J18<=O18,"RESTOCK","OK") -> OK
A19: CM012 | B19: Wellman | C19: Suppliment | D19: 44704 | E19: 46528 | F19: =IF(Inventory[[#This Row],[Product Category]]="","",IF(E19<TODAY(),"EXPIRED", IF(E19<=TODAY()+30,"<30 DAYS", IF(E19<=TODAY()+60,"<60 DAYS",IF(E19=0,"",""))))) | G19: 130 | H19: =SUMIF(Purchases[Product ID],A19,Purchases[Quantity]) -> 0 | I19: =SUMIF(Sales[Product Name],Inventory[[#This Row],[Product Name]],Sales[Quantity Sold]) -> 13 | J19: =G19+H19-I19 -> 117 | M19: 15000 | N19: =J19*L19 -> 0 | P19: =IF(J19<=O19,"RESTOCK","OK") -> OK
A20: CM013 | B20: Wellwoman | C20: Suppliment | D20: 44705 | E20: 46134 | F20: =IF(Inventory[[#This Row],[Product Category]]="","",IF(E20<TODAY(),"EXPIRED", IF(E20<=TODAY()+30,"<30 DAYS", IF(E20<=TODAY()+60,"<60 DAYS",IF(E20=0,"",""))))) -> EXPIRED | G20: 170 | H20: =SUMIF(Purchases[Product ID],A20,Purchases[Quantity]) -> 0 | I20: =SUMIF(Sales[Product Name],Inventory[[#This Row],[Product Name]],Sales[Quantity Sold]) -> 20 | J20: =G20+H20-I20 -> 150 | L20: 950 | M20: 5000 | N20: =J20*L20 -> 142500 | P20: =IF(J20<=O20,"RESTOCK","OK") -> OK
A21: CM014 | B21: Gestid | C21: Antiulcer | D21: 44706 | E21: 46896 | F21: =IF(Inventory[[#This Row],[Product Category]]="","",IF(E21<TODAY(),"EXPIRED", IF(E21<=TODAY()+30,"<30 DAYS", IF(E21<=TODAY()+60,"<60 DAYS",IF(E21=0,"",""))))) | G21: 230 | H21: =SUMIF(Purchases[Product ID],A21,Purchases[Quantity]) -> 0 | I21: =SUMIF(Sales[Product Name],Inventory[[#This Row],[Product Name]],Sales[Quantity Sold]) -> 70 | J21: =G21+H21-I21 -> 160 | M21: 4500 | N21: =J21*L21 -> 0 | P21: =IF(J21<=O21,"RESTOCK","OK") -> OK
A22: CM015 | B22: ORS | C22: Suppliment | D22: 44707 | E22: 46897 | F22: =IF(Inventory[[#This Row],[Product Category]]="","",IF(E22<TODAY(),"EXPIRED", IF(E22<=TODAY()+30,"<30 DAYS", IF(E22<=TODAY()+60,"<60 DAYS",IF(E22=0,"",""))))) | G22: 440 | H22: =SUMIF(Purchases[Product ID],A22,Purchases[Quantity]) -> 0 | I22: =SUMIF(Sales[Product Name],Inventory[[#This Row],[Product Name]],Sales[Quantity Sold]) -> 0 | J22: =G22+H22-I22 -> 440 | N22: =J22*L22 -> 0 | P22: =IF(J22<=O22,"RESTOCK","OK") -> OK
A23: CM016 | B23: Yoyo Bitters | C23: Antibiotic | D23: 44708 | E23: 46532 | F23: =IF(Inventory[[#This Row],[Product Category]]="","",IF(E23<TODAY(),"EXPIRED", IF(E23<=TODAY()+30,"<30 DAYS", IF(E23<=TODAY()+60,"<60 DAYS",IF(E23=0,"",""))))) | G23: 95 | H23: =SUMIF(Purchases[Product ID],A23,Purchases[Quantity]) -> 0 | I23: =SUMIF(Sales[Product Name],Inventory[[#This Row],[Product Name]],Sales[Quantity Sold]) -> 0 | J23: =G23+H23-I23 -> 95 | N23: =J23*L23 -> 0 | P23: =IF(J23<=O23,"RESTOCK","OK") -> OK
A24: CM017 | B24: Uniplex | C24: Antibiotic | D24: 44709 | E24: 47264 | F24: =IF(Inventory[[#This Row],[Product Category]]="","",IF(E24<TODAY(),"EXPIRED", IF(E24<=TODAY()+30,"<30 DAYS", IF(E24<=TODAY()+60,"<60 DAYS",IF(E24=0,"",""))))) | G24: 88 | H24: =SUMIF(Purchases[Product ID],A24,Purchases[Quantity]) -> 0 | I24: =SUMIF(Sales[Product Name],Inventory[[#This Row],[Product Name]],Sales[Quantity Sold]) -> 0 | J24: =G24+H24-I24 -> 88 | N24: =J24*L24 -> 0 | P24: =IF(J24<=O24,"RESTOCK","OK") -> OK
A25: CM018 | B25: Ginsomin | C25: Suppliment | D25: 44710 | E25: 46353 | F25: =IF(Inventory[[#This Row],[Product Category]]="","",IF(E25<TODAY(),"EXPIRED", IF(E25<=TODAY()+30,"<30 DAYS", IF(E25<=TODAY()+60,"<60 DAYS",IF(E25=0,"",""))))) | G25: 29 | H25: =SUMIF(Purchases[Product ID],A25,Purchases[Quantity]) -> 0 | I25: =SUMIF(Sales[Product Name],Inventory[[#This Row],[Product Name]],Sales[Quantity Sold]) -> 0 | J25: =G25+H25-I25 -> 29 | N25: =J25*L25 -> 0 | P25: =IF(J25<=O25,"RESTOCK","OK") -> OK
A26: CM019 | B26: Ginsomin Eve | C26: Suppliment | D26: 44711 | E26: 46535 | F26: =IF(Inventory[[#This Row],[Product Category]]="","",IF(E26<TODAY(),"EXPIRED", IF(E26<=TODAY()+30,"<30 DAYS", IF(E26<=TODAY()+60,"<60 DAYS",IF(E26=0,"",""))))) | G26: 145 | H26: =SUMIF(Purchases[Product ID],A26,Purchases[Quantity]) -> 0 | I26: =SUMIF(Sales[Product Name],Inventory[[#This Row],[Product Name]],Sales[Quantity Sold]) -> 15 | J26: =G26+H26-I26 -> 130 | M26: 7500 | N26: =J26*L26 -> 0 | P26: =IF(J26<=O26,"RESTOCK","OK") -> OK
A27: CM020 | B27: Wellkid | C27: Suppliment | D27: 44712 | E27: 46385 | F27: =IF(Inventory[[#This Row],[Product Category]]="","",IF(E27<TODAY(),"EXPIRED", IF(E27<=TODAY()+30,"<30 DAYS", IF(E27<=TODAY()+60,"<60 DAYS",IF(E27=0,"",""))))) | G27: 260 | H27: =SUMIF(Purchases[Product ID],A27,Purchases[Quantity]) -> 0 | I27: =SUMIF(Sales[Product Name],Inventory[[#This Row],[Product Name]],Sales[Quantity Sold]) -> 15 | J27: =G27+H27-I27 -> 245 | N27: =J27*L27 -> 0 | P27: =IF(J27<=O27,"RESTOCK","OK") -> OK
A28: CM021 | B28: Augmentin | C28: Antibiotic | D28: 45731 | E28: 46729 | F28: =IF(Inventory[[#This Row],[Product Category]]="","",IF(E28<TODAY(),"EXPIRED", IF(E28<=TODAY()+30,"<30 DAYS", IF(E28<=TODAY()+60,"<60 DAYS",IF(E28=0,"",""))))) | H28: =SUMIF(Purchases[Product ID],A28,Purchases[Quantity]) -> 0 | I28: =SUMIF(Sales[Product Name],Inventory[[#This Row],[Product Name]],Sales[Quantity Sold]) -> 0 | J28: =G28+H28-I28 -> 0 | N28: =J28*L28 -> 0
A29: CM022 | B29: Neo Presol | C29: Skin Care | D29: 45729 | E29: 46254 | F29: =IF(Inventory[[#This Row],[Product Category]]="","",IF(E29<TODAY(),"EXPIRED", IF(E29<=TODAY()+30,"<30 DAYS", IF(E29<=TODAY()+60,"<60 DAYS",IF(E29=0,"",""))))) -> <60 DAYS | H29: =SUMIF(Purchases[Product ID],A29,Purchases[Quantity]) -> 0 | I29: =SUMIF(Sales[Product Name],Inventory[[#This Row],[Product Name]],Sales[Quantity Sold]) -> 0 | J29: =G29+H29-I29 -> 0 | N29: =J29*L29 -> 0
A30: CM023 | B30: Astymin Syrup 220ml | C30: Supplement | D30: 45695 | E30: 46960 | F30: =IF(Inventory[[#This Row],[Product Category]]="","",IF(E30<TODAY(),"EXPIRED", IF(E30<=TODAY()+30,"<30 DAYS", IF(E30<=TODAY()+60,"<60 DAYS",IF(E30=0,"",""))))) | H30: =SUMIF(Purchases[Product ID],A30,Purchases[Quantity]) -> 0 | I30: =SUMIF(Sales[Product Name],Inventory[[#This Row],[Product Name]],Sales[Quantity Sold]) -> 0 | J30: =G30+H30-I30 -> 0 | N30: =J30*L30 -> 0
F31: =IF(Inventory[[#This Row],[Product Category]]="","",IF(E31<TODAY(),"EXPIRED", IF(E31<=TODAY()+30,"<30 DAYS", IF(E31<=TODAY()+60,"<60 DAYS",IF(E31=0,"",""))))) | H31: =SUMIF(Purchases[Product ID],A31,Purchases[Quantity]) -> 0 | I31: =SUMIF(Sales[Product Name],Inventory[[#This Row],[Product Name]],Sales[Quantity Sold]) -> 0 | J31: =G31+H31-I31 -> 0 | N31: =J31*L31 -> 0
F32: =IF(Inventory[[#This Row],[Product Category]]="","",IF(E32<TODAY(),"EXPIRED", IF(E32<=TODAY()+30,"<30 DAYS", IF(E32<=TODAY()+60,"<60 DAYS",IF(E32=0,"",""))))) | H32: =SUMIF(Purchases[Product ID],A32,Purchases[Quantity]) -> 0 | I32: =SUMIF(Sales[Product Name],Inventory[[#This Row],[Product Name]],Sales[Quantity Sold]) -> 0 | J32: =G32+H32-I32 -> 0 | N32: =J32*L32 -> 0
F33: =IF(Inventory[[#This Row],[Product Category]]="","",IF(E33<TODAY(),"EXPIRED", IF(E33<=TODAY()+30,"<30 DAYS", IF(E33<=TODAY()+60,"<60 DAYS",IF(E33=0,"",""))))) | H33: =SUMIF(Purchases[Product ID],A33,Purchases[Quantity]) -> 0 | I33: =SUMIF(Sales[Product Name],Inventory[[#This Row],[Product Name]],Sales[Quantity Sold]) -> 0 | J33: =G33+H33-I33 -> 0 | N33: =J33*L33 -> 0
F34: =IF(Inventory[[#This Row],[Product Category]]="","",IF(E34<TODAY(),"EXPIRED", IF(E34<=TODAY()+30,"<30 DAYS", IF(E34<=TODAY()+60,"<60 DAYS",IF(E34=0,"",""))))) | H34: =SUMIF(Purchases[Product ID],A34,Purchases[Quantity]) -> 0 | I34: =SUMIF(Sales[Product Name],Inventory[[#This Row],[Product Name]],Sales[Quantity Sold]) -> 0 | J34: =G34+H34-I34 -> 0 | N34: =J34*L34 -> 0
F35: =IF(Inventory[[#This Row],[Product Category]]="","",IF(E35<TODAY(),"EXPIRED", IF(E35<=TODAY()+30,"<30 DAYS", IF(E35<=TODAY()+60,"<60 DAYS",IF(E35=0,"",""))))) | H35: =SUMIF(Purchases[Product ID],A35,Purchases[Quantity]) -> 0 | I35: =SUMIF(Sales[Product Name],Inventory[[#This Row],[Product Name]],Sales[Quantity Sold]) -> 0 | J35: =G35+H35-I35 -> 0 | N35: =J35*L35 -> 0
F36: =IF(Inventory[[#This Row],[Product Category]]="","",IF(E36<TODAY(),"EXPIRED", IF(E36<=TODAY()+30,"<30 DAYS", IF(E36<=TODAY()+60,"<60 DAYS",IF(E36=0,"",""))))) | H36: =SUMIF(Purchases[Product ID],A36,Purchases[Quantity]) -> 0 | I36: =SUMIF(Sales[Product Name],Inventory[[#This Row],[Product Name]],Sales[Quantity Sold]) -> 0 | J36: =G36+H36-I36 -> 0 | N36: =J36*L36 -> 0
F37: =IF(Inventory[[#This Row],[Product Category]]="","",IF(E37<TODAY(),"EXPIRED", IF(E37<=TODAY()+30,"<30 DAYS", IF(E37<=TODAY()+60,"<60 DAYS",IF(E37=0,"",""))))) | H37: =SUMIF(Purchases[Product ID],A37,Purchases[Quantity]) -> 0 | I37: =SUMIF(Sales[Product Name],Inventory[[#This Row],[Product Name]],Sales[Quantity Sold]) -> 0 | J37: =G37+H37-I37 -> 0 | N37: =J37*L37 -> 0
F38: =IF(Inventory[[#This Row],[Product Category]]="","",IF(E38<TODAY(),"EXPIRED", IF(E38<=TODAY()+30,"<30 DAYS", IF(E38<=TODAY()+60,"<60 DAYS",IF(E38=0,"",""))))) | H38: =SUMIF(Purchases[Product ID],A38,Purchases[Quantity]) -> 0 | I38: =SUMIF(Sales[Product Name],Inventory[[#This Row],[Product Name]],Sales[Quantity Sold]) -> 0 | J38: =G38+H38-I38 -> 0 | N38: =J38*L38 -> 0
F39: =IF(Inventory[[#This Row],[Product Category]]="","",IF(E39<TODAY(),"EXPIRED", IF(E39<=TODAY()+30,"<30 DAYS", IF(E39<=TODAY()+60,"<60 DAYS",IF(E39=0,"",""))))) | H39: =SUMIF(Purchases[Product ID],A39,Purchases[Quantity]) -> 0 | I39: =SUMIF(Sales[Product Name],Inventory[[#This Row],[Product Name]],Sales[Quantity Sold]) -> 0 | J39: =G39+H39-I39 -> 0 | N39: =J39*L39 -> 0
F40: =IF(Inventory[[#This Row],[Product Category]]="","",IF(E40<TODAY(),"EXPIRED", IF(E40<=TODAY()+30,"<30 DAYS", IF(E40<=TODAY()+60,"<60 DAYS",IF(E40=0,"",""))))) | H40: =SUMIF(Purchases[Product ID],A40,Purchases[Quantity]) -> 0 | I40: =SUMIF(Sales[Product Name],Inventory[[#This Row],[Product Name]],Sales[Quantity Sold]) -> 0 | J40: =G40+H40-I40 -> 0 | N40: =J40*L40 -> 0
F41: =IF(Inventory[[#This Row],[Product Category]]="","",IF(E41<TODAY(),"EXPIRED", IF(E41<=TODAY()+30,"<30 DAYS", IF(E41<=TODAY()+60,"<60 DAYS",IF(E41=0,"",""))))) | H41: =SUMIF(Purchases[Product ID],A41,Purchases[Quantity]) -> 0 | I41: =SUMIF(Sales[Product Name],Inventory[[#This Row],[Product Name]],Sales[Quantity Sold]) -> 0 | J41: =G41+H41-I41 -> 0 | N41: =J41*L41 -> 0
F42: =IF(Inventory[[#This Row],[Product Category]]="","",IF(E42<TODAY(),"EXPIRED", IF(E42<=TODAY()+30,"<30 DAYS", IF(E42<=TODAY()+60,"<60 DAYS",IF(E42=0,"",""))))) | H42: =SUMIF(Purchases[Product ID],A42,Purchases[Quantity]) -> 0 | I42: =SUMIF(Sales[Product Name],Inventory[[#This Row],[Product Name]],Sales[Quantity Sold]) -> 0 | J42: =G42+H42-I42 -> 0 | N42: =J42*L42 -> 0
... F1006: =IF(Inventory[[#This Row],[Product Category]]="","",IF(E1006<TODAY(),"EXPIRED", IF(E1006<=TODAY()+30,"<30 DAYS", IF(E1006<=TODAY()+60,"<60 DAYS",IF(E1006=0,"",""))))) | H1006: =SUMIF(Purchases[Product ID],A1006,Purchases[Quantity]) -> 0 | I1006: =SUMIF(Sales[Product Name],Inventory[[#This Row],[Product Name]],Sales[Quantity Sold]) -> 0 | J1006: =G1006+H1006-I1006 -> 0 | N1006: =J1006*L1006 -> 0

Sheet Purchases
A1: Date | B1: Supplier | C1: Purchase ID | D1: Product ID | E1: Product Name | F1: Quantity | G1: Unit Cost | H1: Purchase Value
B2: M&B | D2: =_xlfn.XLOOKUP(Purchases[[#This Row],[Product Name]],Inventory[Product Name],Inventory[Product ID]) -> CM001 | E2: Panadol | F2: 10 | G2: 450 | H2: =IF((F2*G2)<>0,F2*G2,"") -> 4500
B3: Pharma | D3: =_xlfn.XLOOKUP(Purchases[[#This Row],[Product Name]],Inventory[Product Name],Inventory[Product ID]) -> CM002 | E3: Babyrex | F3: 17 | G3: 300 | H3: =IF((F3*G3)<>0,F3*G3,"") -> 5100
B4: Biotech | D4: =_xlfn.XLOOKUP(Purchases[[#This Row],[Product Name]],Inventory[Product Name],Inventory[Product ID]) -> CM003 | E4: Lumapril | F4: 10 | G4: 3500 | H4: =IF((F4*G4)<>0,F4*G4,"") -> 35000
B5: Biotech | D5: =_xlfn.XLOOKUP(Purchases[[#This Row],[Product Name]],Inventory[Product Name],Inventory[Product ID]) -> CM004 | E5: Fansidar | F5: 10 | G5: 600 | H5: =IF((F5*G5)<>0,F5*G5,"") -> 6000
B6: Biotech | D6: =_xlfn.XLOOKUP(Purchases[[#This Row],[Product Name]],Inventory[Product Name],Inventory[Product ID]) -> CM005 | E6: Glanil | F6: 10 | G6: 450 | H6: =IF((F6*G6)<>0,F6*G6,"") -> 4500
B7: Biotech | D7: =_xlfn.XLOOKUP(Purchases[[#This Row],[Product Name]],Inventory[Product Name],Inventory[Product ID]) -> CM011 | E7: Perfectil | F7: 10 | G7: 670 | H7: =IF((F7*G7)<>0,F7*G7,"") -> 6700
B8: Biotech | D8: =_xlfn.XLOOKUP(Purchases[[#This Row],[Product Name]],Inventory[Product Name],Inventory[Product ID]) -> CM004 | E8: Fansidar | F8: 10 | G8: 430 | H8: =IF((F8*G8)<>0,F8*G8,"") -> 4300
B9: Pharma | D9: =_xlfn.XLOOKUP(Purchases[[#This Row],[Product Name]],Inventory[Product Name],Inventory[Product ID]) -> CM004 | E9: Fansidar | F9: 10 | G9: 720 | H9: =IF((F9*G9)<>0,F9*G9,"") -> 7200
B10: Pharma | D10: =_xlfn.XLOOKUP(Purchases[[#This Row],[Product Name]],Inventory[Product Name],Inventory[Product ID]) -> CM003 | E10: Lumapril | F10: 10 | G10: 630 | H10: =IF((F10*G10)<>0,F10*G10,"") -> 6300
B11: Pharma | D11: =_xlfn.XLOOKUP(Purchases[[#This Row],[Product Name]],Inventory[Product Name],Inventory[Product ID]) -> CM003 | E11: Lumapril | F11: 10 | G11: 440 | H11: =IF((F11*G11)<>0,F11*G11,"") -> 4400
B12: M&B | D12: =_xlfn.XLOOKUP(Purchases[[#This Row],[Product Name]],Inventory[Product Name],Inventory[Product ID]) -> CM011 | E12: Perfectil | F12: 20 | G12: 710 | H12: =IF((F12*G12)<>0,F12*G12,"") -> 14200
B13: M&B | D13: =IF(_xlfn.XLOOKUP(Purchases[[#This Row],[Product Name]],Inventory[Product Name],Inventory[Product ID])="","",_xlfn.XLOOKUP(Purchases[[#This Row],[Product Name]],Inventory[Product Name],Inventory[Product ID])) -> CM001 | E13: Panadol | F13: 20 | G13: 550 | H13: =IF((F13*G13)<>0,F13*G13,"") -> 11000
B14: Biotech | D14: =IF(_xlfn.XLOOKUP(Purchases[[#This Row],[Product Name]],Inventory[Product Name],Inventory[Product ID])="","",_xlfn.XLOOKUP(Purchases[[#This Row],[Product Name]],Inventory[Product Name],Inventory[Product ID])) -> CM001 | E14: Panadol | F14: 30 | G14: 820 | H14: =IF((F14*G14)<>0,F14*G14,"") -> 24600
B15: Biotech | D15: =IF(_xlfn.XLOOKUP(Purchases[[#This Row],[Product Name]],Inventory[Product Name],Inventory[Product ID])="","",_xlfn.XLOOKUP(Purchases[[#This Row],[Product Name]],Inventory[Product Name],Inventory[Product ID])) -> CM002 | E15: Babyrex | F15: 3 | G15: 600 | H15: =IF((F15*G15)<>0,F15*G15,"") -> 1800
D16: =IF(_xlfn.XLOOKUP(Purchases[[#This Row],[Product Name]],Inventory[Product Name],Inventory[Product ID])="","",_xlfn.XLOOKUP(Purchases[[#This Row],[Product Name]],Inventory[Product Name],Inventory[Product ID])) | H16: =IF((F16*G16)<>0,F16*G16,"")
D17: =IF(_xlfn.XLOOKUP(Purchases[[#This Row],[Product Name]],Inventory[Product Name],Inventory[Product ID])="","",_xlfn.XLOOKUP(Purchases[[#This Row],[Product Name]],Inventory[Product Name],Inventory[Product ID])) | H17: =IF((F17*G17)<>0,F17*G17,"")
D18: =IF(_xlfn.XLOOKUP(Purchases[[#This Row],[Product Name]],Inventory[Product Name],Inventory[Product ID])="","",_xlfn.XLOOKUP(Purchases[[#This Row],[Product Name]],Inventory[Product Name],Inventory[Product ID])) | H18: =IF((F18*G18)<>0,F18*G18,"")
D19: =IF(_xlfn.XLOOKUP(Purchases[[#This Row],[Product Name]],Inventory[Product Name],Inventory[Product ID])="","",_xlfn.XLOOKUP(Purchases[[#This Row],[Product Name]],Inventory[Product Name],Inventory[Product ID])) | H19: =IF((F19*G19)<>0,F19*G19,"")
D20: =IF(_xlfn.XLOOKUP(Purchases[[#This Row],[Product Name]],Inventory[Product Name],Inventory[Product ID])="","",_xlfn.XLOOKUP(Purchases[[#This Row],[Product Name]],Inventory[Product Name],Inventory[Product ID])) | H20: =IF((F20*G20)<>0,F20*G20,"")
D21: =IF(_xlfn.XLOOKUP(Purchases[[#This Row],[Product Name]],Inventory[Product Name],Inventory[Product ID])="","",_xlfn.XLOOKUP(Purchases[[#This Row],[Product Name]],Inventory[Product Name],Inventory[Product ID])) | H21: =IF((F21*G21)<>0,F21*G21,"")
D22: =IF(_xlfn.XLOOKUP(Purchases[[#This Row],[Product Name]],Inventory[Product Name],Inventory[Product ID])="","",_xlfn.XLOOKUP(Purchases[[#This Row],[Product Name]],Inventory[Product Name],Inventory[Product ID])) | H22: =IF((F22*G22)<>0,F22*G22,"")
D23: =IF(_xlfn.XLOOKUP(Purchases[[#This Row],[Product Name]],Inventory[Product Name],Inventory[Product ID])="","",_xlfn.XLOOKUP(Purchases[[#This Row],[Product Name]],Inventory[Product Name],Inventory[Product ID])) | H23: =IF((F23*G23)<>0,F23*G23,"")
D24: =IF(_xlfn.XLOOKUP(Purchases[[#This Row],[Product Name]],Inventory[Product Name],Inventory[Product ID])="","",_xlfn.XLOOKUP(Purchases[[#This Row],[Product Name]],Inventory[Product Name],Inventory[Product ID])) | H24: =IF((F24*G24)<>0,F24*G24,"")
D25: =IF(_xlfn.XLOOKUP(Purchases[[#This Row],[Product Name]],Inventory[Product Name],Inventory[Product ID])="","",_xlfn.XLOOKUP(Purchases[[#This Row],[Product Name]],Inventory[Product Name],Inventory[Product ID])) | H25: =IF((F25*G25)<>0,F25*G25,"")
D26: =IF(_xlfn.XLOOKUP(Purchases[[#This Row],[Product Name]],Inventory[Product Name],Inventory[Product ID])="","",_xlfn.XLOOKUP(Purchases[[#This Row],[Product Name]],Inventory[Product Name],Inventory[Product ID])) | H26: =IF((F26*G26)<>0,F26*G26,"")
D27: =IF(_xlfn.XLOOKUP(Purchases[[#This Row],[Product Name]],Inventory[Product Name],Inventory[Product ID])="","",_xlfn.XLOOKUP(Purchases[[#This Row],[Product Name]],Inventory[Product Name],Inventory[Product ID])) | H27: =IF((F27*G27)<>0,F27*G27,"")
... D2000: =IF(_xlfn.XLOOKUP(Purchases[[#This Row],[Product Name]],Inventory[Product Name],Inventory[Product ID])="","",_xlfn.XLOOKUP(Purchases[[#This Row],[Product Name]],Inventory[Product Name],Inventory[Product ID])) | H2000: =IF((F2000*G2000)<>0,F2000*G2000,"")

Sheet Sales
A1: COUNT OF SALE | B1: TOTAL SALES TODAY | C1: NIGHT SALE | D1: DAY SALE | E1: ACTUAL SALES | F1: Total Discount | G1: NET SALES | H1: Total Cash | I1: Total Transfer | J1: Total POS
A2: =COUNTIF(Sales[Date],TODAY()) -> 0 | B2: =SUMIF(Sales[Date],TODAY(),Sales[Sales Value]) -> 0 | C2: =SUMIFS(Sales[Sales Value],Sales[Work Shift],"Day",Sales[Date],TODAY()) -> 0 | D2: =SUMIFS(Sales[Sales Value],Sales[Work Shift],"Night",Sales[Date],TODAY()) -> 0 | E2: =SUMIF(Sales[Sales Status],"",Sales[Sales Value]) -> 896700 | F2: =SUM(Sales[Discount]) -> 0 | G2: =E2-F2 -> 896700 | H2: =SUMIF(Sales[Payment Mode],"Cash",Sales[Sales Value]) -> 14000 | I2: =SUMIF(Sales[Payment Mode],"Transfer",Sales[Sales Value]) -> 27500 | J2: =SUMIF(Sales[Payment Mode],"POS",Sales[Sales Value]) -> 90000
A5: Invoice no | B5: Work Shift | C5: Date | D5: Sale ID | E5: Product ID | F5: Product Name | G5: Quantity Sold | H5: Unit Price | I5: Sales Value | J5: Discount | K5: Sales Status | L5: Payment Mode
A6: 1 | B6: Day | C6: 46174 | D6: =IF(Sales[[#This Row],[Product ID]]="","",Sales[[#This Row],[Date]]&Sales[[#This Row],[Invoice no]]) -> 461741 | E6: =IF(_xlfn.XLOOKUP(Sales[[#This Row],[Product Name]],Inventory[Product Name],Inventory[Product ID],"-")="","",_xlfn.XLOOKUP(Sales[[#This Row],[Product Name]],Inventory[Product Name],Inventory[Product ID],"-")) -> CM001 | F6: Panadol | G6: 20 | H6: =IF(_xlfn.XLOOKUP(Sales[[#This Row],[Product Name]],Inventory[Product Name],Inventory[Sale Price],"")=0,"",_xlfn.XLOOKUP(Sales[[#This Row],[Product Name]],Inventory[Product Name],Inventory[Sale Price])) -> 700 | I6: =IFERROR(G6*H6,"") -> 14000 | L6: Cash
A7: 2 | B7: Day | C7: 46176 | D7: =IF(Sales[[#This Row],[Product ID]]="","",Sales[[#This Row],[Date]]&Sales[[#This Row],[Invoice no]]) -> 461762 | E7: =IF(_xlfn.XLOOKUP(Sales[[#This Row],[Product Name]],Inventory[Product Name],Inventory[Product ID],"-")="","",_xlfn.XLOOKUP(Sales[[#This Row],[Product Name]],Inventory[Product Name],Inventory[Product ID],"-")) -> CM002 | F7: Babyrex | G7: 15 | H7: =IF(_xlfn.XLOOKUP(Sales[[#This Row],[Product Name]],Inventory[Product Name],Inventory[Sale Price],"")=0,"",_xlfn.XLOOKUP(Sales[[#This Row],[Product Name]],Inventory[Product Name],Inventory[Sale Price])) -> 500 | I7: =IFERROR(G7*H7,"") -> 7500 | K7: Pay Later | L7: Transfer | P7: =if(NOW()<6:00:00,"Day","Night")
A8: 3 | B8: Day | C8: 46176 | D8: =IF(Sales[[#This Row],[Product ID]]="","",Sales[[#This Row],[Date]]&Sales[[#This Row],[Invoice no]]) -> 461763 | E8: =IF(_xlfn.XLOOKUP(Sales[[#This Row],[Product Name]],Inventory[Product Name],Inventory[Product ID],"-")="","",_xlfn.XLOOKUP(Sales[[#This Row],[Product Name]],Inventory[Product Name],Inventory[Product ID],"-")) -> CM014 | F8: Gestid | G8: 20 | H8: =IF(_xlfn.XLOOKUP(Sales[[#This Row],[Product Name]],Inventory[Product Name],Inventory[Sale Price],"")=0,"",_xlfn.XLOOKUP(Sales[[#This Row],[Product Name]],Inventory[Product Name],Inventory[Sale Price])) -> 4500 | I8: =IFERROR(G8*H8,"") -> 90000 | L8: POS
A9: 4 | B9: Day | C9: 46176 | D9: =IF(Sales[[#This Row],[Product ID]]="","",Sales[[#This Row],[Date]]&Sales[[#This Row],[Invoice no]]) -> 461764 | E9: =IF(_xlfn.XLOOKUP(Sales[[#This Row],[Product Name]],Inventory[Product Name],Inventory[Product ID],"-")="","",_xlfn.XLOOKUP(Sales[[#This Row],[Product Name]],Inventory[Product Name],Inventory[Product ID],"-")) -> CM004 | F9: Fansidar | G9: 15 | H9: =IF(_xlfn.XLOOKUP(Sales[[#This Row],[Product Name]],Inventory[Product Name],Inventory[Sale Price],"")=0,"",_xlfn.XLOOKUP(Sales[[#This Row],[Product Name]],Inventory[Product Name],Inventory[Sale Price])) -> 800 | I9: =IFERROR(G9*H9,"") -> 12000 | O9: =NOW() -> 46203.883
A10: 5 | B10: Day | C10: 46176 | D10: =IF(Sales[[#This Row],[Product ID]]="","",Sales[[#This Row],[Date]]&Sales[[#This Row],[Invoice no]]) -> 461765 | E10: =IF(_xlfn.XLOOKUP(Sales[[#This Row],[Product Name]],Inventory[Product Name],Inventory[Product ID],"-")="","",_xlfn.XLOOKUP(Sales[[#This Row],[Product Name]],Inventory[Product Name],Inventory[Product ID],"-")) -> CM005 | F10: Glanil | G10: 20 | H10: =IF(_xlfn.XLOOKUP(Sales[[#This Row],[Product Name]],Inventory[Product Name],Inventory[Sale Price],"")=0,"",_xlfn.XLOOKUP(Sales[[#This Row],[Product Name]],Inventory[Product Name],Inventory[Sale Price])) -> 1000 | I10: =IFERROR(G10*H10,"") -> 20000 | L10: Transfer
A11: 6 | B11: Night | C11: 46178 | D11: =IF(Sales[[#This Row],[Product ID]]="","",Sales[[#This Row],[Date]]&Sales[[#This Row],[Invoice no]]) -> 461786 | E11: =IF(_xlfn.XLOOKUP(Sales[[#This Row],[Product Name]],Inventory[Product Name],Inventory[Product ID],"-")="","",_xlfn.XLOOKUP(Sales[[#This Row],[Product Name]],Inventory[Product Name],Inventory[Product ID],"-")) -> CM002 | F11: Babyrex | G11: 15 | H11: =IF(_xlfn.XLOOKUP(Sales[[#This Row],[Product Name]],Inventory[Product Name],Inventory[Sale Price],"")=0,"",_xlfn.XLOOKUP(Sales[[#This Row],[Product Name]],Inventory[Product Name],Inventory[Sale Price])) -> 500 | I11: =IFERROR(G11*H11,"") -> 7500
A12: 7 | B12: Day | C12: 46178 | D12: =IF(Sales[[#This Row],[Product ID]]="","",Sales[[#This Row],[Date]]&Sales[[#This Row],[Invoice no]]) -> 461787 | E12: =IF(_xlfn.XLOOKUP(Sales[[#This Row],[Product Name]],Inventory[Product Name],Inventory[Product ID],"-")="","",_xlfn.XLOOKUP(Sales[[#This Row],[Product Name]],Inventory[Product Name],Inventory[Product ID],"-")) -> CM012 | F12: Wellman | G12: 10 | H12: =IF(_xlfn.XLOOKUP(Sales[[#This Row],[Product Name]],Inventory[Product Name],Inventory[Sale Price],"")=0,"",_xlfn.XLOOKUP(Sales[[#This Row],[Product Name]],Inventory[Product Name],Inventory[Sale Price])) -> 15000 | I12: =IFERROR(G12*H12,"") -> 150000
A13: 8 | B13: Night | C13: 46178 | D13: =IF(Sales[[#This Row],[Product ID]]="","",Sales[[#This Row],[Date]]&Sales[[#This Row],[Invoice no]]) -> 461788 | E13: =IF(_xlfn.XLOOKUP(Sales[[#This Row],[Product Name]],Inventory[Product Name],Inventory[Product ID],"-")="","",_xlfn.XLOOKUP(Sales[[#This Row],[Product Name]],Inventory[Product Name],Inventory[Product ID],"-")) -> CM005 | F13: Glanil | G13: 15 | H13: =IF(_xlfn.XLOOKUP(Sales[[#This Row],[Product Name]],Inventory[Product Name],Inventory[Sale Price],"")=0,"",_xlfn.XLOOKUP(Sales[[#This Row],[Product Name]],Inventory[Product Name],Inventory[Sale Price])) -> 1000 | I13: =IFERROR(G13*H13,"") -> 15000
A14: 9 | B14: Night | C14: 46178 | D14: =IF(Sales[[#This Row],[Product ID]]="","",Sales[[#This Row],[Date]]&Sales[[#This Row],[Invoice no]]) -> 461789 | E14: =IF(_xlfn.XLOOKUP(Sales[[#This Row],[Product Name]],Inventory[Product Name],Inventory[Product ID],"-")="","",_xlfn.XLOOKUP(Sales[[#This Row],[Product Name]],Inventory[Product Name],Inventory[Product ID],"-")) -> CM013 | F14: Wellwoman | G14: 20 | H14: =IF(_xlfn.XLOOKUP(Sales[[#This Row],[Product Name]],Inventory[Product Name],Inventory[Sale Price],"")=0,"",_xlfn.XLOOKUP(Sales[[#This Row],[Product Name]],Inventory[Product Name],Inventory[Sale Price])) -> 5000 | I14: =IFERROR(G14*H14,"") -> 100000
A15: 10 | B15: Night | C15: 46194 | D15: =IF(Sales[[#This Row],[Product ID]]="","",Sales[[#This Row],[Date]]&Sales[[#This Row],[Invoice no]]) -> 4619410 | E15: =IF(_xlfn.XLOOKUP(Sales[[#This Row],[Product Name]],Inventory[Product Name],Inventory[Product ID],"-")="","",_xlfn.XLOOKUP(Sales[[#This Row],[Product Name]],Inventory[Product Name],Inventory[Product ID],"-")) -> CM014 | F15: Gestid | G15: 30 | H15: =IF(_xlfn.XLOOKUP(Sales[[#This Row],[Product Name]],Inventory[Product Name],Inventory[Sale Price],"")=0,"",_xlfn.XLOOKUP(Sales[[#This Row],[Product Name]],Inventory[Product Name],Inventory[Sale Price])) -> 4500 | I15: =IFERROR(G15*H15,"") -> 135000
A16: 11 | B16: Night | C16: 46194 | D16: =IF(Sales[[#This Row],[Product ID]]="","",Sales[[#This Row],[Date]]&Sales[[#This Row],[Invoice no]]) -> 4619411 | E16: =IF(_xlfn.XLOOKUP(Sales[[#This Row],[Product Name]],Inventory[Product Name],Inventory[Product ID],"-")="","",_xlfn.XLOOKUP(Sales[[#This Row],[Product Name]],Inventory[Product Name],Inventory[Product ID],"-")) -> CM005 | F16: Glanil | G16: 25 | H16: =IF(_xlfn.XLOOKUP(Sales[[#This Row],[Product Name]],Inventory[Product Name],Inventory[Sale Price],"")=0,"",_xlfn.XLOOKUP(Sales[[#This Row],[Product Name]],Inventory[Product Name],Inventory[Sale Price])) -> 1000 | I16: =IFERROR(G16*H16,"") -> 25000
A17: 12 | B17: Night | C17: 46194 | D17: =IF(Sales[[#This Row],[Product ID]]="","",Sales[[#This Row],[Date]]&Sales[[#This Row],[Invoice no]]) -> 4619412 | E17: =IF(_xlfn.XLOOKUP(Sales[[#This Row],[Product Name]],Inventory[Product Name],Inventory[Product ID],"-")="","",_xlfn.XLOOKUP(Sales[[#This Row],[Product Name]],Inventory[Product Name],Inventory[Product ID],"-")) -> CM020 | F17: Wellkid | G17: 15 | H17: =IF(_xlfn.XLOOKUP(Sales[[#This Row],[Product Name]],Inventory[Product Name],Inventory[Sale Price],"")=0,"",_xlfn.XLOOKUP(Sales[[#This Row],[Product Name]],Inventory[Product Name],Inventory[Sale Price])) | I17: =IFERROR(G17*H17,"")
A18: 13 | B18: Day | C18: 46194 | D18: =IF(Sales[[#This Row],[Product ID]]="","",Sales[[#This Row],[Date]]&Sales[[#This Row],[Invoice no]]) -> 4619413 | E18: =IF(_xlfn.XLOOKUP(Sales[[#This Row],[Product Name]],Inventory[Product Name],Inventory[Product ID],"-")="","",_xlfn.XLOOKUP(Sales[[#This Row],[Product Name]],Inventory[Product Name],Inventory[Product ID],"-")) -> CM014 | F18: Gestid | G18: 20 | H18: =IF(_xlfn.XLOOKUP(Sales[[#This Row],[Product Name]],Inventory[Product Name],Inventory[Sale Price],"")=0,"",_xlfn.XLOOKUP(Sales[[#This Row],[Product Name]],Inventory[Product Name],Inventory[Sale Price])) -> 4500 | I18: =IFERROR(G18*H18,"") -> 90000
A19: 14 | B19: Night | C19: 46194 | D19: =IF(Sales[[#This Row],[Product ID]]="","",Sales[[#This Row],[Date]]&Sales[[#This Row],[Invoice no]]) -> 4619414 | E19: =IF(_xlfn.XLOOKUP(Sales[[#This Row],[Product Name]],Inventory[Product Name],Inventory[Product ID],"-")="","",_xlfn.XLOOKUP(Sales[[#This Row],[Product Name]],Inventory[Product Name],Inventory[Product ID],"-")) -> CM019 | F19: Ginsomin Eve | G19: 15 | H19: =IF(_xlfn.XLOOKUP(Sales[[#This Row],[Product Name]],Inventory[Product Name],Inventory[Sale Price],"")=0,"",_xlfn.XLOOKUP(Sales[[#This Row],[Product Name]],Inventory[Product Name],Inventory[Sale Price])) -> 7500 | I19: =IFERROR(G19*H19,"") -> 112500
A20: 15 | C20: 46194 | D20: =IF(Sales[[#This Row],[Product ID]]="","",Sales[[#This Row],[Date]]&Sales[[#This Row],[Invoice no]]) -> 4619415 | E20: =IF(_xlfn.XLOOKUP(Sales[[#This Row],[Product Name]],Inventory[Product Name],Inventory[Product ID],"-")="","",_xlfn.XLOOKUP(Sales[[#This Row],[Product Name]],Inventory[Product Name],Inventory[Product ID],"-")) -> CM008 | F20: Strepsil | G20: 20 | H20: =IF(_xlfn.XLOOKUP(Sales[[#This Row],[Product Name]],Inventory[Product Name],Inventory[Sale Price],"")=0,"",_xlfn.XLOOKUP(Sales[[#This Row],[Product Name]],Inventory[Product Name],Inventory[Sale Price])) -> 700 | I20: =IFERROR(G20*H20,"") -> 14000
A21: 16 | C21: 46194 | D21: =IF(Sales[[#This Row],[Product ID]]="","",Sales[[#This Row],[Date]]&Sales[[#This Row],[Invoice no]]) -> 4619416 | E21: =IF(_xlfn.XLOOKUP(Sales[[#This Row],[Product Name]],Inventory[Product Name],Inventory[Product ID],"-")="","",_xlfn.XLOOKUP(Sales[[#This Row],[Product Name]],Inventory[Product Name],Inventory[Product ID],"-")) -> CM008 | F21: Strepsil | G21: 5 | H21: =IF(_xlfn.XLOOKUP(Sales[[#This Row],[Product Name]],Inventory[Product Name],Inventory[Sale Price],"")=0,"",_xlfn.XLOOKUP(Sales[[#This Row],[Product Name]],Inventory[Product Name],Inventory[Sale Price])) -> 700 | I21: =IFERROR(G21*H21,"") -> 3500
A22: 17 | C22: 46194 | D22: =IF(Sales[[#This Row],[Product ID]]="","",Sales[[#This Row],[Date]]&Sales[[#This Row],[Invoice no]]) -> 4619417 | E22: =IF(_xlfn.XLOOKUP(Sales[[#This Row],[Product Name]],Inventory[Product Name],Inventory[Product ID],"-")="","",_xlfn.XLOOKUP(Sales[[#This Row],[Product Name]],Inventory[Product Name],Inventory[Product ID],"-")) -> CM012 | F22: Wellman | G22: 3 | H22: =IF(_xlfn.XLOOKUP(Sales[[#This Row],[Product Name]],Inventory[Product Name],Inventory[Sale Price],"")=0,"",_xlfn.XLOOKUP(Sales[[#This Row],[Product Name]],Inventory[Product Name],Inventory[Sale Price])) -> 15000 | I22: =IFERROR(G22*H22,"") -> 45000
A23: 18 | C23: 46194 | D23: =IF(Sales[[#This Row],[Product ID]]="","",Sales[[#This Row],[Date]]&Sales[[#This Row],[Invoice no]]) -> 4619418 | E23: =IF(_xlfn.XLOOKUP(Sales[[#This Row],[Product Name]],Inventory[Product Name],Inventory[Product ID],"-")="","",_xlfn.XLOOKUP(Sales[[#This Row],[Product Name]],Inventory[Product Name],Inventory[Product ID],"-")) -> CM003 | F23: Lumapril | G23: 4 | H23: =IF(_xlfn.XLOOKUP(Sales[[#This Row],[Product Name]],Inventory[Product Name],Inventory[Sale Price],"")=0,"",_xlfn.XLOOKUP(Sales[[#This Row],[Product Name]],Inventory[Product Name],Inventory[Sale Price])) -> 300 | I23: =IFERROR(G23*H23,"") -> 1200
A24: 19 | C24: 46194 | D24: =IF(Sales[[#This Row],[Product ID]]="","",Sales[[#This Row],[Date]]&Sales[[#This Row],[Invoice no]]) -> 4619419 | E24: =IF(_xlfn.XLOOKUP(Sales[[#This Row],[Product Name]],Inventory[Product Name],Inventory[Product ID],"-")="","",_xlfn.XLOOKUP(Sales[[#This Row],[Product Name]],Inventory[Product Name],Inventory[Product ID],"-")) -> CM002 | F24: Babyrex | G24: 7 | H24: =IF(_xlfn.XLOOKUP(Sales[[#This Row],[Product Name]],Inventory[Product Name],Inventory[Sale Price],"")=0,"",_xlfn.XLOOKUP(Sales[[#This Row],[Product Name]],Inventory[Product Name],Inventory[Sale Price])) -> 500 | I24: =IFERROR(G24*H24,"") -> 3500
A25: 20 | C25: 46194 | D25: =IF(Sales[[#This Row],[Product ID]]="","",Sales[[#This Row],[Date]]&Sales[[#This Row],[Invoice no]]) -> 4619420 | E25: =IF(_xlfn.XLOOKUP(Sales[[#This Row],[Product Name]],Inventory[Product Name],Inventory[Product ID],"-")="","",_xlfn.XLOOKUP(Sales[[#This Row],[Product Name]],Inventory[Product Name],Inventory[Product ID],"-")) -> CM001 | F25: Panadol | G25: 53 | H25: =IF(_xlfn.XLOOKUP(Sales[[#This Row],[Product Name]],Inventory[Product Name],Inventory[Sale Price],"")=0,"",_xlfn.XLOOKUP(Sales[[#This Row],[Product Name]],Inventory[Product Name],Inventory[Sale Price])) -> 700 | I25: =IFERROR(G25*H25,"") -> 37100
A26: 21 | C26: 46194 | D26: =IF(Sales[[#This Row],[Product ID]]="","",Sales[[#This Row],[Date]]&Sales[[#This Row],[Invoice no]]) -> 4619421 | E26: =IF(_xlfn.XLOOKUP(Sales[[#This Row],[Product Name]],Inventory[Product Name],Inventory[Product ID],"-")="","",_xlfn.XLOOKUP(Sales[[#This Row],[Product Name]],Inventory[Product Name],Inventory[Product ID],"-")) -> CM005 | F26: Glanil | G26: 6 | H26: =IF(_xlfn.XLOOKUP(Sales[[#This Row],[Product Name]],Inventory[Product Name],Inventory[Sale Price],"")=0,"",_xlfn.XLOOKUP(Sales[[#This Row],[Product Name]],Inventory[Product Name],Inventory[Sale Price])) -> 1000 | I26: =IFERROR(G26*H26,"") -> 6000
A27: 22 | D27: =IF(Sales[[#This Row],[Product ID]]="","",Sales[[#This Row],[Date]]&Sales[[#This Row],[Invoice no]]) -> 22 | E27: =IF(_xlfn.XLOOKUP(Sales[[#This Row],[Product Name]],Inventory[Product Name],Inventory[Product ID],"-")="","",_xlfn.XLOOKUP(Sales[[#This Row],[Product Name]],Inventory[Product Name],Inventory[Product ID],"-")) -> CM002 | F27: Babyrex | G27: 6 | H27: =IF(_xlfn.XLOOKUP(Sales[[#This Row],[Product Name]],Inventory[Product Name],Inventory[Sale Price],"")=0,"",_xlfn.XLOOKUP(Sales[[#This Row],[Product Name]],Inventory[Product Name],Inventory[Sale Price])) -> 500 | I27: =IFERROR(G27*H27,"") -> 3000
A28: 23 | D28: =IF(Sales[[#This Row],[Product ID]]="","",Sales[[#This Row],[Date]]&Sales[[#This Row],[Invoice no]]) -> 23 | E28: =IF(_xlfn.XLOOKUP(Sales[[#This Row],[Product Name]],Inventory[Product Name],Inventory[Product ID],"-")="","",_xlfn.XLOOKUP(Sales[[#This Row],[Product Name]],Inventory[Product Name],Inventory[Product ID],"-")) -> CM002 | F28: Babyrex | G28: 7 | H28: =IF(_xlfn.XLOOKUP(Sales[[#This Row],[Product Name]],Inventory[Product Name],Inventory[Sale Price],"")=0,"",_xlfn.XLOOKUP(Sales[[#This Row],[Product Name]],Inventory[Product Name],Inventory[Sale Price])) -> 500 | I28: =IFERROR(G28*H28,"") -> 3500
A29: 24 | D29: =IF(Sales[[#This Row],[Product ID]]="","",Sales[[#This Row],[Date]]&Sales[[#This Row],[Invoice no]]) -> 24 | E29: =IF(_xlfn.XLOOKUP(Sales[[#This Row],[Product Name]],Inventory[Product Name],Inventory[Product ID],"-")="","",_xlfn.XLOOKUP(Sales[[#This Row],[Product Name]],Inventory[Product Name],Inventory[Product ID],"-")) -> CM004 | F29: Fansidar | H29: =IF(_xlfn.XLOOKUP(Sales[[#This Row],[Product Name]],Inventory[Product Name],Inventory[Sale Price],"")=0,"",_xlfn.XLOOKUP(Sales[[#This Row],[Product Name]],Inventory[Product Name],Inventory[Sale Price])) -> 800 | I29: =IFERROR(G29*H29,"") -> 0
A30: 25 | D30: =IF(Sales[[#This Row],[Product ID]]="","",Sales[[#This Row],[Date]]&Sales[[#This Row],[Invoice no]]) -> 25 | E30: =IF(_xlfn.XLOOKUP(Sales[[#This Row],[Product Name]],Inventory[Product Name],Inventory[Product ID],"-")="","",_xlfn.XLOOKUP(Sales[[#This Row],[Product Name]],Inventory[Product Name],Inventory[Product ID],"-")) -> CM001 | F30: Panadol | G30: 7 | H30: =IF(_xlfn.XLOOKUP(Sales[[#This Row],[Product Name]],Inventory[Product Name],Inventory[Sale Price],"")=0,"",_xlfn.XLOOKUP(Sales[[#This Row],[Product Name]],Inventory[Product Name],Inventory[Sale Price])) -> 700 | I30: =IFERROR(G30*H30,"") -> 4900
A31: 26 | D31: =IF(Sales[[#This Row],[Product ID]]="","",Sales[[#This Row],[Date]]&Sales[[#This Row],[Invoice no]]) -> 26 | E31: =IF(_xlfn.XLOOKUP(Sales[[#This Row],[Product Name]],Inventory[Product Name],Inventory[Product ID],"-")="","",_xlfn.XLOOKUP(Sales[[#This Row],[Product Name]],Inventory[Product Name],Inventory[Product ID],"-")) -> CM004 | F31: Fansidar | G31: 5 | H31: =IF(_xlfn.XLOOKUP(Sales[[#This Row],[Product Name]],Inventory[Product Name],Inventory[Sale Price],"")=0,"",_xlfn.XLOOKUP(Sales[[#This Row],[Product Name]],Inventory[Product Name],Inventory[Sale Price])) -> 800 | I31: =IFERROR(G31*H31,"") -> 4000
A32: 27 | D32: =IF(Sales[[#This Row],[Product ID]]="","",Sales[[#This Row],[Date]]&Sales[[#This Row],[Invoice no]]) | E32: =IF(_xlfn.XLOOKUP(Sales[[#This Row],[Product Name]],Inventory[Product Name],Inventory[Product ID],"-")="","",_xlfn.XLOOKUP(Sales[[#This Row],[Product Name]],Inventory[Product Name],Inventory[Product ID],"-")) | H32: =IF(_xlfn.XLOOKUP(Sales[[#This Row],[Product Name]],Inventory[Product Name],Inventory[Sale Price],"")=0,"",_xlfn.XLOOKUP(Sales[[#This Row],[Product Name]],Inventory[Product Name],Inventory[Sale Price])) | I32: =IFERROR(G32*H32,"")
A33: 28 | D33: =IF(Sales[[#This Row],[Product ID]]="","",Sales[[#This Row],[Date]]&Sales[[#This Row],[Invoice no]]) | E33: =IF(_xlfn.XLOOKUP(Sales[[#This Row],[Product Name]],Inventory[Product Name],Inventory[Product ID],"-")="","",_xlfn.XLOOKUP(Sales[[#This Row],[Product Name]],Inventory[Product Name],Inventory[Product ID],"-")) | H33: =IF(_xlfn.XLOOKUP(Sales[[#This Row],[Product Name]],Inventory[Product Name],Inventory[Sale Price],"")=0,"",_xlfn.XLOOKUP(Sales[[#This Row],[Product Name]],Inventory[Product Name],Inventory[Sale Price])) | I33: =IFERROR(G33*H33,"")
A34: 29 | D34: =IF(Sales[[#This Row],[Product ID]]="","",Sales[[#This Row],[Date]]&Sales[[#This Row],[Invoice no]]) | E34: =IF(_xlfn.XLOOKUP(Sales[[#This Row],[Product Name]],Inventory[Product Name],Inventory[Product ID],"-")="","",_xlfn.XLOOKUP(Sales[[#This Row],[Product Name]],Inventory[Product Name],Inventory[Product ID],"-")) | H34: =IF(_xlfn.XLOOKUP(Sales[[#This Row],[Product Name]],Inventory[Product Name],Inventory[Sale Price],"")=0,"",_xlfn.XLOOKUP(Sales[[#This Row],[Product Name]],Inventory[Product Name],Inventory[Sale Price])) | I34: =IFERROR(G34*H34,"")
A35: 30 | D35: =IF(Sales[[#This Row],[Product ID]]="","",Sales[[#This Row],[Date]]&Sales[[#This Row],[Invoice no]]) | E35: =IF(_xlfn.XLOOKUP(Sales[[#This Row],[Product Name]],Inventory[Product Name],Inventory[Product ID],"-")="","",_xlfn.XLOOKUP(Sales[[#This Row],[Product Name]],Inventory[Product Name],Inventory[Product ID],"-")) | H35: =IF(_xlfn.XLOOKUP(Sales[[#This Row],[Product Name]],Inventory[Product Name],Inventory[Sale Price],"")=0,"",_xlfn.XLOOKUP(Sales[[#This Row],[Product Name]],Inventory[Product Name],Inventory[Sale Price])) | I35: =IFERROR(G35*H35,"")
A36: 31 | D36: =IF(Sales[[#This Row],[Product ID]]="","",Sales[[#This Row],[Date]]&Sales[[#This Row],[Invoice no]]) | E36: =IF(_xlfn.XLOOKUP(Sales[[#This Row],[Product Name]],Inventory[Product Name],Inventory[Product ID],"-")="","",_xlfn.XLOOKUP(Sales[[#This Row],[Product Name]],Inventory[Product Name],Inventory[Product ID],"-")) | H36: =IF(_xlfn.XLOOKUP(Sales[[#This Row],[Product Name]],Inventory[Product Name],Inventory[Sale Price],"")=0,"",_xlfn.XLOOKUP(Sales[[#This Row],[Product Name]],Inventory[Product Name],Inventory[Sale Price])) | I36: =IFERROR(G36*H36,"")
A37: 32 | D37: =IF(Sales[[#This Row],[Product ID]]="","",Sales[[#This Row],[Date]]&Sales[[#This Row],[Invoice no]]) | E37: =IF(_xlfn.XLOOKUP(Sales[[#This Row],[Product Name]],Inventory[Product Name],Inventory[Product ID],"-")="","",_xlfn.XLOOKUP(Sales[[#This Row],[Product Name]],Inventory[Product Name],Inventory[Product ID],"-")) | H37: =IF(_xlfn.XLOOKUP(Sales[[#This Row],[Product Name]],Inventory[Product Name],Inventory[Sale Price],"")=0,"",_xlfn.XLOOKUP(Sales[[#This Row],[Product Name]],Inventory[Product Name],Inventory[Sale Price])) | I37: =IFERROR(G37*H37,"")
A38: 33 | D38: =IF(Sales[[#This Row],[Product ID]]="","",Sales[[#This Row],[Date]]&Sales[[#This Row],[Invoice no]]) | E38: =IF(_xlfn.XLOOKUP(Sales[[#This Row],[Product Name]],Inventory[Product Name],Inventory[Product ID],"-")="","",_xlfn.XLOOKUP(Sales[[#This Row],[Product Name]],Inventory[Product Name],Inventory[Product ID],"-")) | H38: =IF(_xlfn.XLOOKUP(Sales[[#This Row],[Product Name]],Inventory[Product Name],Inventory[Sale Price],"")=0,"",_xlfn.XLOOKUP(Sales[[#This Row],[Product Name]],Inventory[Product Name],Inventory[Sale Price])) | I38: =IFERROR(G38*H38,"")
A39: 34 | D39: =IF(Sales[[#This Row],[Product ID]]="","",Sales[[#This Row],[Date]]&Sales[[#This Row],[Invoice no]]) | E39: =IF(_xlfn.XLOOKUP(Sales[[#This Row],[Product Name]],Inventory[Product Name],Inventory[Product ID],"-")="","",_xlfn.XLOOKUP(Sales[[#This Row],[Product Name]],Inventory[Product Name],Inventory[Product ID],"-")) | H39: =IF(_xlfn.XLOOKUP(Sales[[#This Row],[Product Name]],Inventory[Product Name],Inventory[Sale Price],"")=0,"",_xlfn.XLOOKUP(Sales[[#This Row],[Product Name]],Inventory[Product Name],Inventory[Sale Price])) | I39: =IFERROR(G39*H39,"")
A40: 35 | D40: =IF(Sales[[#This Row],[Product ID]]="","",Sales[[#This Row],[Date]]&Sales[[#This Row],[Invoice no]]) | E40: =IF(_xlfn.XLOOKUP(Sales[[#This Row],[Product Name]],Inventory[Product Name],Inventory[Product ID],"-")="","",_xlfn.XLOOKUP(Sales[[#This Row],[Product Name]],Inventory[Product Name],Inventory[Product ID],"-")) | H40: =IF(_xlfn.XLOOKUP(Sales[[#This Row],[Product Name]],Inventory[Product Name],Inventory[Sale Price],"")=0,"",_xlfn.XLOOKUP(Sales[[#This Row],[Product Name]],Inventory[Product Name],Inventory[Sale Price])) | I40: =IFERROR(G40*H40,"")
A41: 36 | D41: =IF(Sales[[#This Row],[Product ID]]="","",Sales[[#This Row],[Date]]&Sales[[#This Row],[Invoice no]]) | E41: =IF(_xlfn.XLOOKUP(Sales[[#This Row],[Product Name]],Inventory[Product Name],Inventory[Product ID],"-")="","",_xlfn.XLOOKUP(Sales[[#This Row],[Product Name]],Inventory[Product Name],Inventory[Product ID],"-")) | H41: =IF(_xlfn.XLOOKUP(Sales[[#This Row],[Product Name]],Inventory[Product Name],Inventory[Sale Price],"")=0,"",_xlfn.XLOOKUP(Sales[[#This Row],[Product Name]],Inventory[Product Name],Inventory[Sale Price])) | I41: =IFERROR(G41*H41,"")
A42: 37 | D42: =IF(Sales[[#This Row],[Product ID]]="","",Sales[[#This Row],[Date]]&Sales[[#This Row],[Invoice no]]) | E42: =IF(_xlfn.XLOOKUP(Sales[[#This Row],[Product Name]],Inventory[Product Name],Inventory[Product ID],"-")="","",_xlfn.XLOOKUP(Sales[[#This Row],[Product Name]],Inventory[Product Name],Inventory[Product ID],"-")) | H42: =IF(_xlfn.XLOOKUP(Sales[[#This Row],[Product Name]],Inventory[Product Name],Inventory[Sale Price],"")=0,"",_xlfn.XLOOKUP(Sales[[#This Row],[Product Name]],Inventory[Product Name],Inventory[Sale Price])) | I42: =IFERROR(G42*H42,"")
...

Sheet Suppliers
A1: Supplier ID | B1: Supplier Name | C1: Phone | D1: Email | E1: Address
A2: CMS001 | B2: M&B
A3: CMS002 | B3: Pharma
A4: CMS003 | B4: Biotech

Sheet Dashboard
A1: PHARMACY KPI DASHBOARD
A3: Total Inventory Value | B3: =SUM(Inventory!N:N) -> 1089500
A4: Total Sales Value | B4: =SUM(Sales!I:I) -> 931700
A5: Total Purchase Value | B5: =SUM(Purchases!H:H) -> 135600
A6: Expired Products | B6: =COUNTIF(Inventory!F:F,"EXPIRED") -> 4
A7: Products Requiring Restock | B7: =COUNTIF(Inventory!P:P,"RESTOCK") -> 1

Sheet Directory
A2: Unit Size | B2: Sales Status | C2: Work Shift | D2: Payment Mode
A3: Pack | B3: Paid | C3: Day | D3: Cash
A4: Sachet | B4: Pay Later | C4: Night | D4: Transfer
A5: Bottle | D5: POS
A6: Piece
A7: Tablet
A8: Tin
A9: Roll

Sheet Data Summerization
A3: Product Category | B3: Sum of Sold Qty
A4: Analgesic | B4: 130
A5: Antibiotic | B5: 24
A6: Antidiabetic | B6: 66
A7: Antimalaria | B7: 15
A8: Antiulcer | B8: 50
A9: Suppliment | B9: 88
A10: (blank) | B10: 0
A11: Grand Total | B11: 373
